Traceback (most recent call last):
  File "/Users/etyagi/opt/anaconda3/envs/pug/lib/python3.7/site-packages/jupyter_cache/executors/utils.py", line 56, in single_nb_execution
    record_timing=False,
  File "/Users/etyagi/opt/anaconda3/envs/pug/lib/python3.7/site-packages/nbclient/client.py", line 1204, in execute
    return NotebookClient(nb=nb, resources=resources, km=km, **kwargs).execute()
  File "/Users/etyagi/opt/anaconda3/envs/pug/lib/python3.7/site-packages/nbclient/util.py", line 84, in wrapped
    return just_run(coro(*args, **kwargs))
  File "/Users/etyagi/opt/anaconda3/envs/pug/lib/python3.7/site-packages/nbclient/util.py", line 62, in just_run
    return loop.run_until_complete(coro)
  File "/Users/etyagi/opt/anaconda3/envs/pug/lib/python3.7/asyncio/base_events.py", line 587, in run_until_complete
    return future.result()
  File "/Users/etyagi/opt/anaconda3/envs/pug/lib/python3.7/site-packages/nbclient/client.py", line 664, in async_execute
    cell, index, execution_count=self.code_cells_executed + 1
  File "/Users/etyagi/opt/anaconda3/envs/pug/lib/python3.7/site-packages/nbclient/client.py", line 965, in async_execute_cell
    await self._check_raise_for_error(cell, cell_index, exec_reply)
  File "/Users/etyagi/opt/anaconda3/envs/pug/lib/python3.7/site-packages/nbclient/client.py", line 862, in _check_raise_for_error
    raise CellExecutionError.from_cell_and_msg(cell, exec_reply_content)
nbclient.exceptions.CellExecutionError: An error occurred while executing the following cell:
------------------
new_tuple = (0, 0, 0)
new_tuple[1]  = 100
------------------

[0;31m---------------------------------------------------------------------------[0m
[0;31mTypeError[0m                                 Traceback (most recent call last)
[0;32m/var/folders/2h/x_c0jljd4zjfr1md5dcj8ts40000gp/T/ipykernel_6080/635166011.py[0m in [0;36m<module>[0;34m[0m
[1;32m      1[0m [0mnew_tuple[0m [0;34m=[0m [0;34m([0m[0;36m0[0m[0;34m,[0m [0;36m0[0m[0;34m,[0m [0;36m0[0m[0;34m)[0m[0;34m[0m[0;34m[0m[0m
[0;32m----> 2[0;31m [0mnew_tuple[0m[0;34m[[0m[0;36m1[0m[0;34m][0m  [0;34m=[0m [0;36m100[0m[0;34m[0m[0;34m[0m[0m
[0m
[0;31mTypeError[0m: 'tuple' object does not support item assignment
TypeError: 'tuple' object does not support item assignment

